Workbook

Sheet dados_obs_edq
A1: JDAY | B1: Data | C1: Cota | D1: Volume (Hm3) | E1: Volume (%) | F1: TempAgua(C) | G1: Evaporacao(hm3) | H1: Fosforo Total (mg/L P) | I1: Nitrogenio total (mg/L) | J1: Fosfato(mg/L) | K1: Nitrito-Nitrato(mg/L) | L1: chla_obs | M1: do_obs
A2: 1 | B2: 42370 | C2: 185.86 | D2: 22.912704 | E2: =D2/250.5 -> 0.091467879 | F2: =IFERROR(VLOOKUP(B2,'EDQ-01'!$B$12:$AR$115,43,FALSE()),-999) -> -999 | G2: 0.020690598 | H2: =IFERROR(VLOOKUP(B2,'EDQ-01'!$B$12:$AR$115,25,FALSE()),-999) -> -999 | I2: =IFERROR(VLOOKUP(B2,'EDQ-01'!$B$12:$AR$115,30,FALSE()),-999) -> -999 | J2: =IFERROR(0.4*H2," ") -> -399.6 | K2: =IFERROR(0.3*I2," ") -> -299.7 | L2: -999 | M2: -999
A3: 2 | B3: 42371 | C3: 185.85 | D3: 22.864616 | E3: =D3/250.5 -> 0.091275911 | F3: =IFERROR(VLOOKUP(B3,'EDQ-01'!$B$12:$AR$115,43,FALSE()),-999) -> -999 | G3: 0.020656097 | H3: =IFERROR(VLOOKUP(B3,'EDQ-01'!$B$12:$AR$115,25,FALSE()),-999) -> -999 | I3: =IFERROR(VLOOKUP(B3,'EDQ-01'!$B$12:$AR$115,30,FALSE()),-999) -> -999 | J3: =IFERROR(0.4*H3," ") -> -399.6 | K3: =IFERROR(0.3*I3," ") -> -299.7 | L3: -999 | M3: -999
A4: 3 | B4: 42372 | C4: 185.85 | D4: 22.864616 | E4: =D4/250.5 -> 0.091275911 | F4: =IFERROR(VLOOKUP(B4,'EDQ-01'!$B$12:$AR$115,43,FALSE()),-999) -> -999 | G4: 0.020656097 | H4: =IFERROR(VLOOKUP(B4,'EDQ-01'!$B$12:$AR$115,25,FALSE()),-999) -> -999 | I4: =IFERROR(VLOOKUP(B4,'EDQ-01'!$B$12:$AR$115,30,FALSE()),-999) -> -999 | J4: =IFERROR(0.4*H4," ") -> -399.6 | K4: =IFERROR(0.3*I4," ") -> -299.7 | L4: -999 | M4: -999
A5: 4 | B5: 42373 | C5: 185.84 | D5: 22.816599 | E5: =D5/250.5 -> 0.091084227 | F5: =IFERROR(VLOOKUP(B5,'EDQ-01'!$B$12:$AR$115,43,FALSE()),-999) -> -999 | G5: 0.02062164 | H5: =IFERROR(VLOOKUP(B5,'EDQ-01'!$B$12:$AR$115,25,FALSE()),-999) -> -999 | I5: =IFERROR(VLOOKUP(B5,'EDQ-01'!$B$12:$AR$115,30,FALSE()),-999) -> -999 | J5: =IFERROR(0.4*H5," ") -> -399.6 | K5: =IFERROR(0.3*I5," ") -> -299.7 | L5: -999 | M5: -999
A6: 5 | B6: 42374 | C6: 185.83 | D6: 22.768653 | E6: =D6/250.5 -> 0.090892825 | F6: =IFERROR(VLOOKUP(B6,'EDQ-01'!$B$12:$AR$115,43,FALSE()),-999) -> -999 | G6: 0.020587226 | H6: =IFERROR(VLOOKUP(B6,'EDQ-01'!$B$12:$AR$115,25,FALSE()),-999) -> -999 | I6: =IFERROR(VLOOKUP(B6,'EDQ-01'!$B$12:$AR$115,30,FALSE()),-999) -> -999 | J6: =IFERROR(0.4*H6," ") -> -399.6 | K6: =IFERROR(0.3*I6," ") -> -299.7 | L6: -999 | M6: -999
A7: 6 | B7: 42375 | C7: 185.82 | D7: 22.720778 | E7: =D7/250.5 -> 0.090701707 | F7: =IFERROR(VLOOKUP(B7,'EDQ-01'!$B$12:$AR$115,43,FALSE()),-999) -> -999 | G7: 0.020552856 | H7: =IFERROR(VLOOKUP(B7,'EDQ-01'!$B$12:$AR$115,25,FALSE()),-999) -> -999 | I7: =IFERROR(VLOOKUP(B7,'EDQ-01'!$B$12:$AR$115,30,FALSE()),-999) -> -999 | J7: =IFERROR(0.4*H7," ") -> -399.6 | K7: =IFERROR(0.3*I7," ") -> -299.7 | L7: -999 | M7: -999
A8: 7 | B8: 42376 | C8: 185.82 | D8: 22.720778 | E8: =D8/250.5 -> 0.090701707 | F8: =IFERROR(VLOOKUP(B8,'EDQ-01'!$B$12:$AR$115,43,FALSE()),-999) -> -999 | G8: 0.020552856 | H8: =IFERROR(VLOOKUP(B8,'EDQ-01'!$B$12:$AR$115,25,FALSE()),-999) -> -999 | I8: =IFERROR(VLOOKUP(B8,'EDQ-01'!$B$12:$AR$115,30,FALSE()),-999) -> -999 | J8: =IFERROR(0.4*H8," ") -> -399.6 | K8: =IFERROR(0.3*I8," ") -> -299.7 | L8: -999 | M8: -999
A9: 8 | B9: 42377 | C9: 185.81 | D9: 22.672973 | E9: =D9/250.5 -> 0.090510871 | F9: =IFERROR(VLOOKUP(B9,'EDQ-01'!$B$12:$AR$115,43,FALSE()),-999) -> -999 | G9: 0.020518528 | H9: =IFERROR(VLOOKUP(B9,'EDQ-01'!$B$12:$AR$115,25,FALSE()),-999) -> -999 | I9: =IFERROR(VLOOKUP(B9,'EDQ-01'!$B$12:$AR$115,30,FALSE()),-999) -> -999 | J9: =IFERROR(0.4*H9," ") -> -399.6 | K9: =IFERROR(0.3*I9," ") -> -299.7 | L9: -999 | M9: -999
A10: 9 | B10: 42378 | C10: 185.8 | D10: 22.625239 | E10: =D10/250.5 -> 0.090320317 | F10: =IFERROR(VLOOKUP(B10,'EDQ-01'!$B$12:$AR$115,43,FALSE()),-999) -> -999 | G10: 0.020484243 | H10: =IFERROR(VLOOKUP(B10,'EDQ-01'!$B$12:$AR$115,25,FALSE()),-999) -> -999 | I10: =IFERROR(VLOOKUP(B10,'EDQ-01'!$B$12:$AR$115,30,FALSE()),-999) -> -999 | J10: =IFERROR(0.4*H10," ") -> -399.6 | K10: =IFERROR(0.3*I10," ") -> -299.7 | L10: -999 | M10: -999
A11: 10 | B11: 42379 | C11: 185.8 | D11: 22.625239 | E11: =D11/250.5 -> 0.090320317 | F11: =IFERROR(VLOOKUP(B11,'EDQ-01'!$B$12:$AR$115,43,FALSE()),-999) -> -999 | G11: 0.020484243 | H11: =IFERROR(VLOOKUP(B11,'EDQ-01'!$B$12:$AR$115,25,FALSE()),-999) -> -999 | I11: =IFERROR(VLOOKUP(B11,'EDQ-01'!$B$12:$AR$115,30,FALSE()),-999) -> -999 | J11: =IFERROR(0.4*H11," ") -> -399.6 | K11: =IFERROR(0.3*I11," ") -> -299.7 | L11: -999 | M11: -999
A12: 11 | B12: 42380 | C12: 185.8 | D12: 22.625239 | E12: =D12/250.5 -> 0.090320317 | F12: =IFERROR(VLOOKUP(B12,'EDQ-01'!$B$12:$AR$115,43,FALSE()),-999) -> -999 | G12: 0.020484243 | H12: =IFERROR(VLOOKUP(B12,'EDQ-01'!$B$12:$AR$115,25,FALSE()),-999) -> -999 | I12: =IFERROR(VLOOKUP(B12,'EDQ-01'!$B$12:$AR$115,30,FALSE()),-999) -> -999 | J12: =IFERROR(0.4*H12," ") -> -399.6 | K12: =IFERROR(0.3*I12," ") -> -299.7 | L12: -999 | M12: -999
A13: 12 | B13: 42381 | C13: 185.8 | D13: 22.625239 | E13: =D13/250.5 -> 0.090320317 | F13: =IFERROR(VLOOKUP(B13,'EDQ-01'!$B$12:$AR$115,43,FALSE()),-999) -> -999 | G13: 0.020484243 | H13: =IFERROR(VLOOKUP(B13,'EDQ-01'!$B$12:$AR$115,25,FALSE()),-999) -> -999 | I13: =IFERROR(VLOOKUP(B13,'EDQ-01'!$B$12:$AR$115,30,FALSE()),-999) -> -999 | J13: =IFERROR(0.4*H13," ") -> -399.6 | K13: =IFERROR(0.3*I13," ") -> -299.7 | L13: -999 | M13: -999
... A2193: 2192 | B2193: 44561 | C2193: 194.18 | D2193: 92.961306 | E2193: =D2193/250.5 -> 0.37110302 | F2193: =IFERROR(VLOOKUP(B2193,'EDQ-01'!$B$12:$AR$115,43,FALSE()),-999) -> -999 | G2193: 0.083278584 | H2193: =IFERROR(VLOOKUP(B2193,'EDQ-01'!$B$12:$AR$115,25,FALSE()),-999) -> -999 | I2193: =IFERROR(VLOOKUP(B2193,'EDQ-01'!$B$12:$AR$115,30,FALSE()),-999) -> -999 | J2193: =IFERROR(0.4*H2193," ") -> -399.6 | K2193: =IFERROR(0.3*I2193," ") -> -299.7 | L2193: -999 | M2193: -999

Sheet dados_obs_evp_edq
A1: JDAY | B1: Data | C1: Cota | D1: Volume (Hm³) | E1: Volume (%) | F1: Temperatura Água (ºC) | G1: Fósforo Total (mg/L P) | H1: Nitrogênio total (mg/L) | I1: Fosfato(mg/L) | J1: Nitrito-Nitrato(mg/L)
A2: 1 | B2: 42370 | C2: 185.86 | D2: 22.912704 | E2: =D2/250.5 -> 0.091467879 | F2: =IFERROR(VLOOKUP(B2,'EDQ-01'!$B$12:$AR$115,43,FALSE()),-999) -> -999 | G2: =IFERROR(VLOOKUP(B2,'EDQ-01'!$B$12:$AR$115,25,FALSE()),-999) -> -999 | H2: =IFERROR(VLOOKUP(B2,'EDQ-01'!$B$12:$AR$115,30,FALSE()),-999) -> -999 | I2: =IFERROR(0.4*G2," ") -> -399.6 | J2: =IFERROR(0.3*H2," ") -> -299.7
A3: 2 | B3: 42371 | C3: 185.85 | D3: 22.864616 | E3: =D3/250.5 -> 0.091275911 | F3: =IFERROR(VLOOKUP(B3,'EDQ-01'!$B$12:$AR$115,43,FALSE()),-999) -> -999 | G3: =IFERROR(VLOOKUP(B3,'EDQ-01'!$B$12:$AR$115,25,FALSE()),-999) -> -999 | H3: =IFERROR(VLOOKUP(B3,'EDQ-01'!$B$12:$AR$115,30,FALSE()),-999) -> -999 | I3: =IFERROR(0.4*G3," ") -> -399.6 | J3: =IFERROR(0.3*H3," ") -> -299.7
A4: 3 | B4: 42372 | C4: 185.85 | D4: 22.864616 | E4: =D4/250.5 -> 0.091275911 | F4: =IFERROR(VLOOKUP(B4,'EDQ-01'!$B$12:$AR$115,43,FALSE()),-999) -> -999 | G4: =IFERROR(VLOOKUP(B4,'EDQ-01'!$B$12:$AR$115,25,FALSE()),-999) -> -999 | H4: =IFERROR(VLOOKUP(B4,'EDQ-01'!$B$12:$AR$115,30,FALSE()),-999) -> -999 | I4: =IFERROR(0.4*G4," ") -> -399.6 | J4: =IFERROR(0.3*H4," ") -> -299.7
A5: 4 | B5: 42373 | C5: 185.84 | D5: 22.816599 | E5: =D5/250.5 -> 0.091084227 | F5: =IFERROR(VLOOKUP(B5,'EDQ-01'!$B$12:$AR$115,43,FALSE()),-999) -> -999 | G5: =IFERROR(VLOOKUP(B5,'EDQ-01'!$B$12:$AR$115,25,FALSE()),-999) -> -999 | H5: =IFERROR(VLOOKUP(B5,'EDQ-01'!$B$12:$AR$115,30,FALSE()),-999) -> -999 | I5: =IFERROR(0.4*G5," ") -> -399.6 | J5: =IFERROR(0.3*H5," ") -> -299.7
A6: 5 | B6: 42374 | C6: 185.83 | D6: 22.768653 | E6: =D6/250.5 -> 0.090892825 | F6: =IFERROR(VLOOKUP(B6,'EDQ-01'!$B$12:$AR$115,43,FALSE()),-999) -> -999 | G6: =IFERROR(VLOOKUP(B6,'EDQ-01'!$B$12:$AR$115,25,FALSE()),-999) -> -999 | H6: =IFERROR(VLOOKUP(B6,'EDQ-01'!$B$12:$AR$115,30,FALSE()),-999) -> -999 | I6: =IFERROR(0.4*G6," ") -> -399.6 | J6: =IFERROR(0.3*H6," ") -> -299.7
A7: 6 | B7: 42375 | C7: 185.82 | D7: 22.720778 | E7: =D7/250.5 -> 0.090701707 | F7: =IFERROR(VLOOKUP(B7,'EDQ-01'!$B$12:$AR$115,43,FALSE()),-999) -> -999 | G7: =IFERROR(VLOOKUP(B7,'EDQ-01'!$B$12:$AR$115,25,FALSE()),-999) -> -999 | H7: =IFERROR(VLOOKUP(B7,'EDQ-01'!$B$12:$AR$115,30,FALSE()),-999) -> -999 | I7: =IFERROR(0.4*G7," ") -> -399.6 | J7: =IFERROR(0.3*H7," ") -> -299.7
A8: 7 | B8: 42376 | C8: 185.82 | D8: 22.720778 | E8: =D8/250.5 -> 0.090701707 | F8: =IFERROR(VLOOKUP(B8,'EDQ-01'!$B$12:$AR$115,43,FALSE()),-999) -> -999 | G8: =IFERROR(VLOOKUP(B8,'EDQ-01'!$B$12:$AR$115,25,FALSE()),-999) -> -999 | H8: =IFERROR(VLOOKUP(B8,'EDQ-01'!$B$12:$AR$115,30,FALSE()),-999) -> -999 | I8: =IFERROR(0.4*G8," ") -> -399.6 | J8: =IFERROR(0.3*H8," ") -> -299.7
A9: 8 | B9: 42377 | C9: 185.81 | D9: 22.672973 | E9: =D9/250.5 -> 0.090510871 | F9: =IFERROR(VLOOKUP(B9,'EDQ-01'!$B$12:$AR$115,43,FALSE()),-999) -> -999 | G9: =IFERROR(VLOOKUP(B9,'EDQ-01'!$B$12:$AR$115,25,FALSE()),-999) -> -999 | H9: =IFERROR(VLOOKUP(B9,'EDQ-01'!$B$12:$AR$115,30,FALSE()),-999) -> -999 | I9: =IFERROR(0.4*G9," ") -> -399.6 | J9: =IFERROR(0.3*H9," ") -> -299.7
A10: 9 | B10: 42378 | C10: 185.8 | D10: 22.625239 | E10: =D10/250.5 -> 0.090320317 | F10: =IFERROR(VLOOKUP(B10,'EDQ-01'!$B$12:$AR$115,43,FALSE()),-999) -> -999 | G10: =IFERROR(VLOOKUP(B10,'EDQ-01'!$B$12:$AR$115,25,FALSE()),-999) -> -999 | H10: =IFERROR(VLOOKUP(B10,'EDQ-01'!$B$12:$AR$115,30,FALSE()),-999) -> -999 | I10: =IFERROR(0.4*G10," ") -> -399.6 | J10: =IFERROR(0.3*H10," ") -> -299.7
A11: 10 | B11: 42379 | C11: 185.8 | D11: 22.625239 | E11: =D11/250.5 -> 0.090320317 | F11: =IFERROR(VLOOKUP(B11,'EDQ-01'!$B$12:$AR$115,43,FALSE()),-999) -> -999 | G11: =IFERROR(VLOOKUP(B11,'EDQ-01'!$B$12:$AR$115,25,FALSE()),-999) -> -999 | H11: =IFERROR(VLOOKUP(B11,'EDQ-01'!$B$12:$AR$115,30,FALSE()),-999) -> -999 | I11: =IFERROR(0.4*G11," ") -> -399.6 | J11: =IFERROR(0.3*H11," ") -> -299.7
A12: 11 | B12: 42380 | C12: 185.8 | D12: 22.625239 | E12: =D12/250.5 -> 0.090320317 | F12: =IFERROR(VLOOKUP(B12,'EDQ-01'!$B$12:$AR$115,43,FALSE()),-999) -> -999 | G12: =IFERROR(VLOOKUP(B12,'EDQ-01'!$B$12:$AR$115,25,FALSE()),-999) -> -999 | H12: =IFERROR(VLOOKUP(B12,'EDQ-01'!$B$12:$AR$115,30,FALSE()),-999) -> -999 | I12: =IFERROR(0.4*G12," ") -> -399.6 | J12: =IFERROR(0.3*H12," ") -> -299.7
A13: 12 | B13: 42381 | C13: 185.8 | D13: 22.625239 | E13: =D13/250.5 -> 0.090320317 | F13: =IFERROR(VLOOKUP(B13,'EDQ-01'!$B$12:$AR$115,43,FALSE()),-999) -> -999 | G13: =IFERROR(VLOOKUP(B13,'EDQ-01'!$B$12:$AR$115,25,FALSE()),-999) -> -999 | H13: =IFERROR(VLOOKUP(B13,'EDQ-01'!$B$12:$AR$115,30,FALSE()),-999) -> -999 | I13: =IFERROR(0.4*G13," ") -> -399.6 | J13: =IFERROR(0.3*H13," ") -> -299.7
... A2193: 2192 | B2193: 44561 | C2193: 194.18 | D2193: 92.961306 | E2193: =D2193/250.5 -> 0.37110302 | F2193: =IFERROR(VLOOKUP(B2193,'EDQ-01'!$B$12:$AR$115,43,FALSE()),-999) -> -999 | G2193: =IFERROR(VLOOKUP(B2193,'EDQ-01'!$B$12:$AR$115,25,FALSE()),-999) -> -999 | H2193: =IFERROR(VLOOKUP(B2193,'EDQ-01'!$B$12:$AR$115,30,FALSE()),-999) -> -999 | I2193: =IFERROR(0.4*G2193," ") -> -399.6 | J2193: =IFERROR(0.3*H2193," ") -> -299.7

Sheet EDQ-01
A1: Nome | C1: Açude Edson Queiroz
A2: Ponto | C2: EDQ-01
A3: Latitude | C3: -4.2180977
A4: Longitude | C4: -40.064598
A5: Ref. de localização | C5: Próximo à Barragem
A6: Início do monitoramento | C6: 39580
A7: Última medição | C7: 44755
A8: Nº Total de Parâmetros
A9: Profundidades de coleta | C9: Superfície
C10: Ao longo da coluna d'água:
B11: 1 | C11: 2 | D11: 3 | E11: 4 | F11: 5 | G11: 6 | H11: 7 | I11: 8 | J11: 9 | K11: 10 | L11: 11 | M11: 12 | N11: 13 | O11: 14 | P11: 15 | Q11: 16 | R11: 17 | S11: 18 | T11: 19 | U11: 20 | V11: 21 | W11: 22 | X11: 23 | Y11: 24 | Z11: 25 | AA11: 26 | AB11: 27 | AC11: 28 | AD11: 29 | AE11: 30 | AF11: 31 | AG11: 32 | AH11: 33 | AI11: 34 | AJ11: 35 | AK11: 36 | AL11: 37 | AM11: 38 | AN11: 39 | AO11: 40 | AP11: 41 | AQ11: 42 | AR11: 43
A12: ANO | B12: DATA | C12: PROF | D12: Alcalinidade Bicarbonato (mg/L CaCO3) | E12: Alcalinidade Carbonato (mg/L CaCO3) | F12: Alcalinidade Hidróxido (mg/L CaCO3) | G12: C. Elét. Lab (µS/cm) | H12: C. Elét. Sonda (µS/cm) | I12: Cálcio (mg/L Ca) | J12: Cloretos Lab. (mg/L Cl) | K12: Cloretos Sonda (mg/L Cl) | L12: Clorofila-a Lab. (µg/L) | M12: Clorofila-a Sonda (µg/L) | N12: Colif. Termotolerantes (NMP/100ml) | O12: Colif. Totais (NMP/100mL) | P12: Cont. Cianobacterias Lab (Células/mL) | Q12: Contagem dos Demais Grupos (Células/mL) | R12: Cor Verdadeira (mgPt/L) | S12: DBO (mg/L O2) | T12: DQO (mg/L O2) | U12: Dureza Total (mg/L CaCO3) | V12: Escherichia coli (NMP/100mL) | W12: Feofitina (µg/L) | X12: Ferro (mg/L Fe) | Y12: Ferro dissolvido (mg/L Fe) | Z12: Fósforo Total (mg/L P) | AA12: Magnésio (mg/L Mg) | AB12: Nitratos Lab (mg N-NO3-/L) | AC12: Nitrito (mg N-NO2-/L) | AD12: Nitrogênio Amoniacal Lab (mg N-NH3/L) | AE12: Nitrogênio total (mg/L) | AF12: OD Lab. (mg/L O2) | AG12: OD Sonda (mg/L O2) | AH12: Ortof. Solúvel (mg/L) | AI12: pH Lab | AJ12: pH Sonda | AK12: Potássio (mg/L K) | AL12: Salinidade (porcentagemMil) | AM12: Sódio (mg/L Na) | AN12: Sól. Dissolv. Totais Lab (mg/L) | AO12: Sól. Dissolv. Totais Sonda (g/L) | AP12: Sólidos Totais (mg/L) | AQ12: Sulfatos (mg/L) | AR12: Temperatura Água (ºC) | AS12: Temperatura Ar (ºC) | AT12: Transparência (m) | AU12: Turbidez Lab (NTU) | AV12: Turbidez Sonda (NTU)
B13: 39580 | C13: 0.3 | P13: 97112.9 | Q13: 896
B14: 39581 | C14: 0.3 | D14: 79.3 | E14: 8.95 | F14: 8.95 | G14: 210 | H14: 228 | I14: 21.9 | J14: 32.5 | L14: 30.3 | M14: 11.9 | N14: 15 | O14: 15 | R14: 70 | U14: 27.6 | X14: 0.36 | Z14: 0.01 | AA14: 1.4 | AB14: 0.1 | AC14: 0.01 | AD14: 0.1 | AF14: 2.83 | AG14: 5.18 | AH14: 0.02 | AI14: 7.66 | AJ14: 6.85 | AK14: 5.78 | AM14: 27.2 | AN14: 251 | AQ14: 7.68 | AR14: 28.58 | AU14: 4.6
B15: 39581 | C15: 0.5 | H15: 228 | M15: 11.2 | AG15: 5.17 | AJ15: 6.87 | AR15: 28.59
B16: 39581 | C16: 1 | H16: 228 | M16: 12.4 | AG16: 5.3 | AJ16: 6.92 | AS16: 28.59
B17: 39581 | C17: 2 | H17: 228 | M17: 12.2 | AG17: 5.02 | AJ17: 6.97 | AR17: 28.6
B18: 39581 | C18: 3 | H18: 228 | M18: 12.3 | AG18: 4.92 | AJ18: 7.03 | AR18: 28.6
A19: 2008 | B19: 39581 | C19: 6 | H19: 228 | M19: 11.7 | AG19: 4.79 | AJ19: 7.07 | AR19: 28.57
B20: 39581 | C20: 9 | H20: 182 | M20: 15.2 | AG20: 0.11 | AJ20: 7.08 | AR20: 26.75
B21: 39581 | C21: 12 | H21: 154 | M21: 17 | AG21: 0.06 | AJ21: 7.08 | AR21: 26.35
B22: 39581 | C22: 15 | H22: 143 | M22: 18 | AG22: 0.02 | AJ22: 7.1 | AR22: 26.18
B23: 39581 | C23: 18 | H23: 139 | M23: 17.9 | AG23: 0 | AJ23: 7.16 | AR23: 26.08
B24: 39581 | C24: 21 | H24: 138 | M24: 17 | AJ24: 7.19 | AR24: 26.05
B25: 39581 | C25: 21.5 | H25: 138 | L25: 17.7 | AJ25: 7.25 | AR25: 26.04
B26: 39680 | C26: 0.3 | D26: 91.5 | E26: 8.95 | F26: 8.95 | G26: 193 | H26: 223 | I26: 34.2 | J26: 48.9 | K26: 2.931 | L26: 13.4 | M26: 44.2 | N26: 1 | O26: 4 | P26: 244194.2 | Q26: 1228.5 | R26: 55 | U26: 75.6 | W26: 31.2 | X26: 0.2 | Z26: 0.041 | AA26: 10.1 | AB26: 0.1 | AC26: 0.01 | AD26: 0.1 | AF26: 9.1 | AH26: 0.02 | AI26: 8.41 | AK26: 5.9 | AM26: 30.7 | AN26: 274 | AR26: 28.71 | AU26: 3.9
B27: 39762 | C27: 0.3 | P27: 510822.5 | Q27: 1592.4
B28: 39987 | C28: 0.3 | P28: 328176 | Q28: 206.4 | AR28: 29 | AS28: 29
A29: 2009 | B29: 40032 | C29: 0.3 | P29: 448188 | Q29: 338 | AR29: 28
B30: 40130 | C30: 0.3 | P30: 675508.2
B31: 40304 | C31: 0.3 | D31: 60.6 | E31: 14.6 | F31: 8.95 | G31: 190 | I31: 11.5 | J31: 27 | L31: 71.6 | N31: 900 | P31: 1495020.8 | Q31: 0 | S31: 5.8 | W31: 18.9 | X31: 0.2 | Z31: 0.09 | AA31: 10.7 | AB31: 0.1 | AC31: 0.01 | AD31: 0.13 | AE31: 0.834 | AH31: 0.02 | AI31: 8.8 | AM31: 35.5 | AN31: 155.5 | AP31: 182.3 | AQ31: 10.4 | AS31: 31 | AU31: 18
B32: 40304 | C32: 4.7 | Z32: 0.08 | AB32: 0.1 | AC32: 0.01 | AD32: 0.125 | AE32: 0.75 | AS32: 31
B33: 40304 | C33: 9.1 | Z33: 0.072 | AB33: 0.1 | AC33: 0.01 | AD33: 0.141 | AE33: 0.712 | AS33: 31
A34: 2010 | B34: 40304 | C34: 13.5 | Z34: 0.085 | AB34: 0.1 | AC34: 0.01 | AD34: 0.158 | AE34: 0.831 | AS34: 31
B35: 40304 | C35: 17.5 | Z35: 0.102 | AB35: 0.1 | AC35: 0.01 | AD35: 0.18 | AE35: 0.931 | AS35: 31
B36: 40395 | C36: 0.3 | P36: 691727.4
B37: 40512 | C37: 0.3 | D37: 77 | E37: 21 | F37: 8.95 | G37: 250 | I37: 14 | J37: 33.5 | L37: 79.3 | P37: 713069.7 | R37: 10 | S37: 6.2 | W37: 5.7 | X37: 0.2 | Z37: 0.137 | AA37: 15.8 | AE37: 0.871 | AH37: 0.02 | AI37: 9.2 | AM37: 38.6 | AN37: 183.3 | AP37: 195 | AQ37: 13.5 | AS37: 31 | AU37: 31.8
B38: 40512 | C38: 15.5 | Z38: 0.201 | AE38: 0.686 | AS38: 31
B39: 40512 | C39: 8 | Z39: 0.137 | AE39: 0.798 | AS39: 31
B40: 40666 | C40: 0.3 | P40: 344968.8 | Q40: 107.4
...
